[2025-06-08T13:33:36.733+0000] {local_task_job_runner.py:120} INFO - ::group::Pre task execution logs
[2025-06-08T13:33:36.787+0000] {taskinstance.py:2076} INFO - Dependencies all met for dep_context=non-requeueable deps ti=<TaskInstance: incremental_data_processor.generate_healthcare_records_data scheduled__2025-06-08T12:00:00+00:00 [queued]>
[2025-06-08T13:33:36.803+0000] {taskinstance.py:2076} INFO - Dependencies all met for dep_context=requeueable deps ti=<TaskInstance: incremental_data_processor.generate_healthcare_records_data scheduled__2025-06-08T12:00:00+00:00 [queued]>
[2025-06-08T13:33:36.806+0000] {taskinstance.py:2306} INFO - Starting attempt 1 of 3
[2025-06-08T13:33:36.826+0000] {taskinstance.py:2330} INFO - Executing <Task(PythonOperator): generate_healthcare_records_data> on 2025-06-08 12:00:00+00:00
[2025-06-08T13:33:36.832+0000] {standard_task_runner.py:63} INFO - Started process 2642 to run task
[2025-06-08T13:33:36.837+0000] {standard_task_runner.py:90} INFO - Running: ['***', 'tasks', 'run', 'incremental_data_processor', 'generate_healthcare_records_data', 'scheduled__2025-06-08T12:00:00+00:00', '--job-id', '149', '--raw', '--subdir', 'DAGS_FOLDER/incremental_data_processor.py', '--cfg-path', '/tmp/tmpr2d4a9i2']
[2025-06-08T13:33:36.841+0000] {standard_task_runner.py:91} INFO - Job 149: Subtask generate_healthcare_records_data
[2025-06-08T13:33:36.924+0000] {task_command.py:426} INFO - Running <TaskInstance: incremental_data_processor.generate_healthcare_records_data scheduled__2025-06-08T12:00:00+00:00 [running]> on host 6211e2649837
[2025-06-08T13:33:37.080+0000] {taskinstance.py:2648} INFO - Exporting env vars: AIRFLOW_CTX_DAG_EMAIL='admin@company.com' AIRFLOW_CTX_DAG_OWNER='***' AIRFLOW_CTX_DAG_ID='incremental_data_processor' AIRFLOW_CTX_TASK_ID='generate_healthcare_records_data' AIRFLOW_CTX_EXECUTION_DATE='2025-06-08T12:00:00+00:00' AIRFLOW_CTX_TRY_NUMBER='1' AIRFLOW_CTX_DAG_RUN_ID='scheduled__2025-06-08T12:00:00+00:00'
[2025-06-08T13:33:37.083+0000] {taskinstance.py:430} INFO - ::endgroup::
[2025-06-08T13:33:37.105+0000] {logging_mixin.py:188} INFO - Generating 800 new rows for healthcare_records starting from ID 0
[2025-06-08T13:33:37.107+0000] {taskinstance.py:441} INFO - ::group::Post task execution logs
[2025-06-08T13:33:37.108+0000] {taskinstance.py:2905} ERROR - Task failed with exception
Traceback (most recent call last):
  File "/home/airflow/.local/lib/python3.9/site-packages/airflow/models/taskinstance.py", line 465, in _execute_task
    result = _execute_callable(context=context, **execute_callable_kwargs)
  File "/home/airflow/.local/lib/python3.9/site-packages/airflow/models/taskinstance.py", line 432, in _execute_callable
    return execute_callable(context=context, **execute_callable_kwargs)
  File "/home/airflow/.local/lib/python3.9/site-packages/airflow/models/baseoperator.py", line 400, in wrapper
    return func(self, *args, **kwargs)
  File "/home/airflow/.local/lib/python3.9/site-packages/airflow/operators/python.py", line 235, in execute
    return_value = self.execute_callable()
  File "/home/airflow/.local/lib/python3.9/site-packages/airflow/operators/python.py", line 252, in execute_callable
    return self.python_callable(*self.op_args, **self.op_kwargs)
  File "/opt/airflow/dags/incremental_data_processor.py", line 320, in generate_incremental_data
    data = generate_healthcare_data(num_rows, start_id)
  File "/opt/airflow/dags/incremental_data_processor.py", line 603, in generate_healthcare_data
    'patient_id': [f"PAT{str(start_id + i + 1).zfill(8)}" for i in range(num_rows)],
  File "/opt/airflow/dags/incremental_data_processor.py", line 603, in <listcomp>
    'patient_id': [f"PAT{str(start_id + i + 1).zfill(8)}" for i in range(num_rows)],
TypeError: can only concatenate str (not "int") to str
[2025-06-08T13:33:37.122+0000] {taskinstance.py:1206} INFO - Marking task as UP_FOR_RETRY. dag_id=incremental_data_processor, task_id=generate_healthcare_records_data, run_id=scheduled__2025-06-08T12:00:00+00:00, execution_date=20250608T120000, start_date=20250608T133336, end_date=20250608T133337
[2025-06-08T13:33:37.154+0000] {logging_mixin.py:188} WARNING - /home/***/.local/lib/python3.9/site-packages/***/utils/email.py:154 RemovedInAirflow3Warning: Fetching SMTP credentials from configuration variables will be deprecated in a future release. Please set credentials using a connection instead.
[2025-06-08T13:33:37.155+0000] {configuration.py:1050} WARNING - section/key [smtp/smtp_user] not found in config
[2025-06-08T13:33:37.157+0000] {email.py:271} INFO - Email alerting: attempt 1
[2025-06-08T13:33:37.168+0000] {configuration.py:1050} WARNING - section/key [smtp/smtp_user] not found in config
[2025-06-08T13:33:37.169+0000] {email.py:271} INFO - Email alerting: attempt 1
[2025-06-08T13:33:37.170+0000] {taskinstance.py:879} ERROR - Failed to send email to: ['admin@company.com']
Traceback (most recent call last):
  File "/home/airflow/.local/lib/python3.9/site-packages/airflow/models/taskinstance.py", line 2479, in _run_raw_task
    self._execute_task_with_callbacks(context, test_mode, session=session)
  File "/home/airflow/.local/lib/python3.9/site-packages/airflow/models/taskinstance.py", line 2676, in _execute_task_with_callbacks
    result = self._execute_task(context, task_orig)
  File "/home/airflow/.local/lib/python3.9/site-packages/airflow/models/taskinstance.py", line 2701, in _execute_task
    return _execute_task(self, context, task_orig)
  File "/home/airflow/.local/lib/python3.9/site-packages/airflow/models/taskinstance.py", line 465, in _execute_task
    result = _execute_callable(context=context, **execute_callable_kwargs)
  File "/home/airflow/.local/lib/python3.9/site-packages/airflow/models/taskinstance.py", line 432, in _execute_callable
    return execute_callable(context=context, **execute_callable_kwargs)
  File "/home/airflow/.local/lib/python3.9/site-packages/airflow/models/baseoperator.py", line 400, in wrapper
    return func(self, *args, **kwargs)
  File "/home/airflow/.local/lib/python3.9/site-packages/airflow/operators/python.py", line 235, in execute
    return_value = self.execute_callable()
  File "/home/airflow/.local/lib/python3.9/site-packages/airflow/operators/python.py", line 252, in execute_callable
    return self.python_callable(*self.op_args, **self.op_kwargs)
  File "/opt/airflow/dags/incremental_data_processor.py", line 320, in generate_incremental_data
    data = generate_healthcare_data(num_rows, start_id)
  File "/opt/airflow/dags/incremental_data_processor.py", line 603, in generate_healthcare_data
    'patient_id': [f"PAT{str(start_id + i + 1).zfill(8)}" for i in range(num_rows)],
  File "/opt/airflow/dags/incremental_data_processor.py", line 603, in <listcomp>
    'patient_id': [f"PAT{str(start_id + i + 1).zfill(8)}" for i in range(num_rows)],
TypeError: can only concatenate str (not "int") to str

During handling of the above exception, another exception occurred:

Traceback (most recent call last):
  File "/home/airflow/.local/lib/python3.9/site-packages/airflow/models/taskinstance.py", line 1063, in _email_alert
    send_email(task.email, subject, html_content)
  File "/home/airflow/.local/lib/python3.9/site-packages/airflow/utils/email.py", line 80, in send_email
    return backend(
  File "/home/airflow/.local/lib/python3.9/site-packages/airflow/utils/email.py", line 154, in send_email_smtp
    send_mime_email(e_from=mail_from, e_to=recipients, mime_msg=msg, conn_id=conn_id, dryrun=dryrun)
  File "/home/airflow/.local/lib/python3.9/site-packages/airflow/utils/email.py", line 273, in send_mime_email
    smtp_conn = _get_smtp_connection(smtp_host, smtp_port, smtp_timeout, smtp_ssl)
  File "/home/airflow/.local/lib/python3.9/site-packages/airflow/utils/email.py", line 317, in _get_smtp_connection
    return smtplib.SMTP(host=host, port=port, timeout=timeout)
  File "/usr/local/lib/python3.9/smtplib.py", line 255, in __init__
    (code, msg) = self.connect(host, port)
  File "/usr/local/lib/python3.9/smtplib.py", line 341, in connect
    self.sock = self._get_socket(host, port, self.timeout)
  File "/usr/local/lib/python3.9/smtplib.py", line 312, in _get_socket
    return socket.create_connection((host, port), timeout,
  File "/usr/local/lib/python3.9/socket.py", line 844, in create_connection
    raise err
  File "/usr/local/lib/python3.9/socket.py", line 832, in create_connection
    sock.connect(sa)
ConnectionRefusedError: [Errno 111] Connection refused

During handling of the above exception, another exception occurred:

Traceback (most recent call last):
  File "/home/airflow/.local/lib/python3.9/site-packages/airflow/models/taskinstance.py", line 877, in _handle_failure
    task_instance.email_alert(error, failure_context["task"])
  File "/home/airflow/.local/lib/python3.9/site-packages/airflow/models/taskinstance.py", line 3163, in email_alert
    _email_alert(task_instance=self, exception=exception, task=task)
  File "/home/airflow/.local/lib/python3.9/site-packages/airflow/models/taskinstance.py", line 1065, in _email_alert
    send_email(task.email, subject, html_content_err)
  File "/home/airflow/.local/lib/python3.9/site-packages/airflow/utils/email.py", line 80, in send_email
    return backend(
  File "/home/airflow/.local/lib/python3.9/site-packages/airflow/utils/email.py", line 154, in send_email_smtp
    send_mime_email(e_from=mail_from, e_to=recipients, mime_msg=msg, conn_id=conn_id, dryrun=dryrun)
  File "/home/airflow/.local/lib/python3.9/site-packages/airflow/utils/email.py", line 273, in send_mime_email
    smtp_conn = _get_smtp_connection(smtp_host, smtp_port, smtp_timeout, smtp_ssl)
  File "/home/airflow/.local/lib/python3.9/site-packages/airflow/utils/email.py", line 317, in _get_smtp_connection
    return smtplib.SMTP(host=host, port=port, timeout=timeout)
  File "/usr/local/lib/python3.9/smtplib.py", line 255, in __init__
    (code, msg) = self.connect(host, port)
  File "/usr/local/lib/python3.9/smtplib.py", line 341, in connect
    self.sock = self._get_socket(host, port, self.timeout)
  File "/usr/local/lib/python3.9/smtplib.py", line 312, in _get_socket
    return socket.create_connection((host, port), timeout,
  File "/usr/local/lib/python3.9/socket.py", line 844, in create_connection
    raise err
  File "/usr/local/lib/python3.9/socket.py", line 832, in create_connection
    sock.connect(sa)
ConnectionRefusedError: [Errno 111] Connection refused
[2025-06-08T13:33:37.192+0000] {standard_task_runner.py:110} ERROR - Failed to execute job 149 for task generate_healthcare_records_data (can only concatenate str (not "int") to str; 2642)
[2025-06-08T13:33:37.231+0000] {local_task_job_runner.py:240} INFO - Task exited with return code 1
[2025-06-08T13:33:37.244+0000] {local_task_job_runner.py:222} INFO - ::endgroup::
