[2025-06-08T12:19:44.662+0000] {scheduler_job_runner.py:769} ERROR - Executor reports task instance <TaskInstance: incremental_data_processor.initialize_tables scheduled__2025-06-08T11:00:00+00:00 [queued]> finished (failed) although the task says it's queued. (Info: None) Was the task killed externally?
