[2025-06-08T14:38:22.539+0000] {local_task_job_runner.py:120} INFO - ::group::Pre task execution logs
[2025-06-08T14:38:22.594+0000] {taskinstance.py:2076} INFO - Dependencies all met for dep_context=non-requeueable deps ti=<TaskInstance: large_csv_processor_dag.process_employees_csv manual__2025-06-08T14:38:18+00:00 [queued]>
[2025-06-08T14:38:22.617+0000] {taskinstance.py:2076} INFO - Dependencies all met for dep_context=requeueable deps ti=<TaskInstance: large_csv_processor_dag.process_employees_csv manual__2025-06-08T14:38:18+00:00 [queued]>
[2025-06-08T14:38:22.618+0000] {taskinstance.py:2306} INFO - Starting attempt 1 of 2
[2025-06-08T14:38:22.635+0000] {taskinstance.py:2330} INFO - Executing <Task(PythonOperator): process_employees_csv> on 2025-06-08 14:38:18+00:00
[2025-06-08T14:38:22.640+0000] {standard_task_runner.py:63} INFO - Started process 602 to run task
[2025-06-08T14:38:22.645+0000] {standard_task_runner.py:90} INFO - Running: ['***', 'tasks', 'run', 'large_csv_processor_dag', 'process_employees_csv', 'manual__2025-06-08T14:38:18+00:00', '--job-id', '221', '--raw', '--subdir', 'DAGS_FOLDER/csv_processor.py', '--cfg-path', '/tmp/tmpvvahvs1o']
[2025-06-08T14:38:22.649+0000] {standard_task_runner.py:91} INFO - Job 221: Subtask process_employees_csv
[2025-06-08T14:38:22.712+0000] {task_command.py:426} INFO - Running <TaskInstance: large_csv_processor_dag.process_employees_csv manual__2025-06-08T14:38:18+00:00 [running]> on host 87e83fb02300
[2025-06-08T14:38:22.815+0000] {taskinstance.py:2648} INFO - Exporting env vars: AIRFLOW_CTX_DAG_OWNER='***' AIRFLOW_CTX_DAG_ID='large_csv_processor_dag' AIRFLOW_CTX_TASK_ID='process_employees_csv' AIRFLOW_CTX_EXECUTION_DATE='2025-06-08T14:38:18+00:00' AIRFLOW_CTX_TRY_NUMBER='1' AIRFLOW_CTX_DAG_RUN_ID='manual__2025-06-08T14:38:18+00:00'
[2025-06-08T14:38:22.817+0000] {taskinstance.py:430} INFO - ::endgroup::
[2025-06-08T14:38:22.835+0000] {taskinstance.py:441} INFO - ::group::Post task execution logs
[2025-06-08T14:38:22.836+0000] {taskinstance.py:2905} ERROR - Task failed with exception
Traceback (most recent call last):
  File "/home/airflow/.local/lib/python3.9/site-packages/airflow/models/taskinstance.py", line 465, in _execute_task
    result = _execute_callable(context=context, **execute_callable_kwargs)
  File "/home/airflow/.local/lib/python3.9/site-packages/airflow/models/taskinstance.py", line 432, in _execute_callable
    return execute_callable(context=context, **execute_callable_kwargs)
  File "/home/airflow/.local/lib/python3.9/site-packages/airflow/models/baseoperator.py", line 400, in wrapper
    return func(self, *args, **kwargs)
  File "/home/airflow/.local/lib/python3.9/site-packages/airflow/operators/python.py", line 235, in execute
    return_value = self.execute_callable()
  File "/home/airflow/.local/lib/python3.9/site-packages/airflow/operators/python.py", line 252, in execute_callable
    return self.python_callable(*self.op_args, **self.op_kwargs)
  File "/opt/airflow/dags/csv_processor.py", line 40, in process_csv_in_chunks
    with open(sql_file_path, 'w') as sql_file:
PermissionError: [Errno 13] Permission denied: './dags/sql/employees_insert.sql'
[2025-06-08T14:38:22.849+0000] {taskinstance.py:1206} INFO - Marking task as UP_FOR_RETRY. dag_id=large_csv_processor_dag, task_id=process_employees_csv, run_id=manual__2025-06-08T14:38:18+00:00, execution_date=20250608T143818, start_date=20250608T143822, end_date=20250608T143822
[2025-06-08T14:38:22.864+0000] {standard_task_runner.py:110} ERROR - Failed to execute job 221 for task process_employees_csv ([Errno 13] Permission denied: './dags/sql/employees_insert.sql'; 602)
[2025-06-08T14:38:22.909+0000] {local_task_job_runner.py:240} INFO - Task exited with return code 1
[2025-06-08T14:38:22.923+0000] {local_task_job_runner.py:222} INFO - ::endgroup::
